<?xml version="1.0" encoding="utf-8"?><testsuites><testsuite name="pytest" errors="0" failures="1" skipped="0" tests="1" time="0.048" timestamp="2022-12-06T14:53:48.312751" hostname="TS01-15"><testcase classname="test_main" name="test_answer" file="test_main.py" line="2" time="0.001"><failure message="assert 4 == 5&#10; +  where 4 = func(3)">def test_answer():
&gt;       assert func(3) == 5
E       assert 4 == 5
E        +  where 4 = func(3)

test_main.py:4: AssertionError</failure><system-out>--------------------------------- Captured Log ---------------------------------

--------------------------------- Captured Out ---------------------------------

</system-out><system-err>--------------------------------- Captured Err ---------------------------------

</system-err></testcase></testsuite></testsuites>